# 15.1 Exception

ในการพัฒนาโปรแกรม จะมี error เกิดขึ้นได้ 2 แบบ
1. Compilation error
   - การผิดพลาดลักษณะนี้ Compiler จะแจ้งเตือน 
2. Run time error
   - การผิดพลาดลักษณะนี้ Compiler จะไม่แจ้งเตือน
   - จะเกิดการ crashes ของโปรแกรมขณะรัน 
   - การ crashes ของโปรแกรมเรียกว่าเกิด Exception

- Exceptions จะเกิดเมื่อโปรแกรมของเราทำงานผิดพลาด 
   - พยายามแปลง invalid string
   - พยายามเข้าถึงสมาชิกอาเรย์ที่อยู่นอกขอบเขต
   - พยายามใช้งานตัวแปร reference ที่เป็น null 
   - …และอีกหลายความพยายาม…
- ภาษา C# มีกลไกรองรับ เพื่อตรวจจับ exceptions ต่างๆ


## 15.1.1 ตัวอย่าง exception 1

รันโปรแกรมต่อไปนี้ แล้วบันทึกผลการรัน

```cs
namespace ExceptionExample
{
    internal class Program
    {
        static void Main(string[] args)
        {
            int i;
            i = int.Parse("10");
            Console.WriteLine($"i = {i}");
            int j;
            j = int.Parse("Ten");
            Console.WriteLine($"j = {j}");
        }
    }
}
```
![image](https://user-images.githubusercontent.com/103983336/236633018-54488078-c5bf-4734-bc7d-7cf221a73fca.png)

## 15.1.2 ตัวอย่าง exception 2

รันโปรแกรมต่อไปนี้ แล้วบันทึกผลการรัน

```cs
namespace ExceptionExample
{
    internal class Program
    {
        static void Main(string[] args)
        {
            int i;
            i = int.Parse("10");
            Console.WriteLine($"i = {i}");

            int j;
            try
            {
                j = int.Parse("Ten");
                Console.WriteLine($"j = {j}");
            }
            catch
            {
                Console.WriteLine("Invalid number.");
            }
        }
    }
}
```
![image](https://user-images.githubusercontent.com/103983336/236633035-98b2e35d-81f2-4a2f-8860-df3d00e1622d.png)


## 15.1.3 Catching exception

รันโปรแกรมต่อไปนี้ แล้วบันทึกผลการรัน


```cs
namespace ExceptionExample
{
    internal class Program
    {
        static void Main(string[] args)
        {
            int i;
            i = int.Parse("10");
            Console.WriteLine($"i = {i}");

            int j;
            try
            {
                j = int.Parse("Ten");
                Console.WriteLine($"j = {j}");
            }
            catch(Exception e)
            {
                Console.WriteLine(e.Message);
                Console.WriteLine(e.StackTrace);
            }
        }
    }
}
```
![image](https://user-images.githubusercontent.com/103983336/236633040-98d5b379-827a-4e26-8709-fbb821fbeca6.png)


## 15.1.4 Try-catch-finally

- บางครั้ง เราอาจต้องการให้โปรแกรมเราทำงานอย่างปกติไม่ว่าจะมี exception เกิดขึ้นหรือไม่
   - การเชื่อมต่อ network ไม่สำเร็จ ต้องทำการยกเลิกการเชื่อมต่อ
   - การเปิดไฟล์แล้วเขียนไม่สำเร็จ ต้องปิดไฟล์นั้น
   - ฯลฯ
- โครงสร้าง try-catch จะมี finally ไว้ให้ทำในสิ่งที่เราต้องการ
- คำสั่งใน finally จะถูกเรียกเสมอ ไม่ว่าจะเกิด exception หรือไม่

รันโปรแกรมต่อไปนี้ แล้วบันทึกผลการรัน


``` cs
namespace ExceptionExample
{
    internal class Program
    {
        static void Main(string[] args)
        {
            Console.WriteLine("--- input string = \"10\" ---");
            int i;
            try
            {
                i = int.Parse("10");
                Console.WriteLine($"i = {i}");
            }
            catch (Exception e)
            {
                Console.WriteLine(e.Message);
                Console.WriteLine(e.StackTrace);
            }
            finally
            {
                Console.WriteLine("Normal routine operation");
            }

            Console.WriteLine("--- input string = \"Ten\" ---");
            int j;
            try
            {
                j = int.Parse("Ten");
                Console.WriteLine($"j = {j}");
            }
            catch(Exception e)
            {
                Console.WriteLine(e.Message);
                Console.WriteLine(e.StackTrace);
            }
            finally 
            {
                Console.WriteLine("Normal routine operation");
            }
            Console.WriteLine("--- End Program ---");
        }
    }
}
```
![image](https://user-images.githubusercontent.com/103983336/236633136-2dcbda57-6943-4e03-92c0-02af6e15c192.png)




