# 15.2 Exception

## 15.2.1 Throw exception

รันโปรแกรมต่อไปนี้ แล้วบันทึกผลการรัน


```cs
namespace ExceptionExample
{
    class CustomException : Exception
    {
        public CustomException(string message)
        {
        }
    }
    internal class Program
    {
        static void Main(string[] args)
        {
            try
            {
                throw new CustomException("Custom exception in TestThrow()");
            }
            catch (CustomException ex)
            {
                Console.WriteLine(ex);
            }
        }
    }
}
```
![image](https://user-images.githubusercontent.com/115037574/236280072-b648aa5a-1598-4fad-ab0a-6535c1a36bae.png)

## 15.2.2 Throw exception

รันโปรแกรมต่อไปนี้ แล้วบันทึกผลการรัน

```cs
using System;
using System.IO;

namespace Exceptions
{
    public class CatchOrder
    {
        public static void Main()
        {
            try
            {
                using (var sw = new StreamWriter("./test.txt"))
                {
                    sw.WriteLine("Hello");
                }
                using (var sr = new StreamReader("./test.txt"))
                {
                    Console.WriteLine(sr.ReadLine());
                }
                using (var sr = new StreamReader("./test1.txt"))
                {
                    Console.WriteLine(sr.ReadLine());
                }
            }
            // Put the more specific exceptions first.
            catch (DirectoryNotFoundException ex)
            {
                Console.WriteLine(ex);
            }
            catch (FileNotFoundException ex)
            {
                Console.WriteLine(ex);
            }
            // Put the least specific exception last.
            catch (IOException ex)
            {
                Console.WriteLine(ex);
            }
            Console.WriteLine("Done");
        }
    }
}
```
![image](https://user-images.githubusercontent.com/115037574/236280411-65dab307-b97e-4549-ba45-8fbe0c014b63.png)
